Workbook
Name Excel_BuiltIn__FilterDatabase_1: '시트2 32품목 스티커'!$A$1:$X$2
Name Excel_BuiltIn_Print_Titles: 시트1!#REF!

Sheet 시트1
F2: 파일에 포함된 제품만 가능하고 **유효기간 2020년부터 2026년 06월** 이전제품만가능 /제품은 원제품 포장에 있는것 만 가능합니다.
B3: %%불용재고 품목 명세서 2026 06 월$$ | O3: 유효기간등록 | P3: 11111 | Q3: 44166
F5: *포는 1포기준 /점안액30A은 1A /ml 통안약은 1통기준 등록
B6: 글씨체 청색 글씨체 50% 적용 | F6: *점안액 % & ml 확인철저히 할것
F7: 하원제약 테라젠 이텍스는 출하건만 가능
A9: 순번 | B9: 제품코드 | C9: 제 조 사 | D9: 발 주 처 | E9: 출 력 명 | F9: 규 격 | G9: 소분수량 | H9: 금액 | I9: 유효기간 | J9: 거래처코드 | K9: 약국명 | L9: 담당자 | M9: 작업일자 | N9: 기준단가 | O9: 거래처도매 | P9: 기준가격×계산단위 | Q9: 보험코드 | R9: 제품명 | S9: 제품구분 | T9: 단위 | U9: 성분분류 | V9: 제형구분 | W9: 제품그룹 | X9: 성 분 | Y9: 표준코드 | Z9: 신고계산단위 | AA9: 비고
A10: 1 | B10: 52308 | C10: 기타제약사 | D10: (주)강선팜 | E10: 린버크서방정 15mg | F10: 28T(PTP) | H10: =G10*N10 -> 0 | N10: 18328 | O10: (주)인천약품 | P10: 513184 | Q10: 624900370 | R10: $$애브 린버크서방정 15mg/28T | S10: 보험(전문) | T10: 정 | U10: 자격요법제(비특이성면역원제제를 포함) | V10: 내복제 | W10: 전문 | X10: upadacitinib hemihydrate (as upadacitinib 15mg) | Y10: 8806249003718 | Z10: 28 | AA10: 18328

Sheet 시트2 32품목 스티커
A1: 순번 | B1: 제품코드 | C1: 제 조 사 | D1: 발 주 처 | E1: 출 력 명 | F1: 규 격 | G1: 소분수량 | H1: 금액 | I1: 유효기간 | J1: 거래처코드 | K1: 약국명 | L1: 담당자 | M1: 작업일자 | N1: 기준단가 | O1: 거래처도매 | P1: 매출 단가 | Q1: 보험코드 | R1: 제 품 명 | S1: 제품 구분 | T1: 단 위 | U1: 성분분류 | V1: 제형 구분 | W1: 제품 그룹 | X1: 성 분 | Y1: 계산단위 | Z1: 구보험코드
A2: 1 | B2: 51320 | C2: (유) 한풍제약 | D2: (유) 한풍제약 | E2: 암로다정 | F2: 30T | H2: =G2*N2 -> 0 | N2: 312 | O2: (주)인천약품 | P2: 9360 | Q2: 658106350 | R2: (품절)한풍 암로다정/30T | S2: 보험(전문) | T2: 1 정 | U2: 혈압강하제 | V2: 내복제 | W2: 전문 | X2: amlodipine besylate (as amlodipine 5mg) | Y2: 8806581063517 | Z2: 30

Sheet 시트3 스티커 발행
A1: 불용재고의약품 | C1: 분류번호 | D1: ='시트2 32품목 스티커'!B2 -> 51320 | G1: 불용재고의약품 | I1: 분류번호 | J1: ='시트2 32품목 스티커'!#REF! -> #REF!
A2: 약 품 명 | B2: ='시트2 32품목 스티커'!E2 -> 암로다정 | C2: 단가 | D2: ='시트2 32품목 스티커'!N2 -> 312 | G2: 약 품 명 | H2: ='시트2 32품목 스티커'!#REF! -> #REF! | I2: 단가 | J2: ='시트2 32품목 스티커'!#REF! -> #REF!
A3: 제약회사 | B3: ='시트2 32품목 스티커'!D2 -> (유) 한풍제약 | C3: 반품금액 | D3: ='시트2 32품목 스티커'!H2 -> 0 | G3: 제약회사 | H3: ='시트2 32품목 스티커'!#REF! -> #REF! | I3: 반품금액 | J3: ='시트2 32품목 스티커'!#REF! -> #REF!
A4: 거래처 | B4: ='시트2 32품목 스티커'!J2 -> 0 | C4: 약 국 명 | D4: ='시트2 32품목 스티커'!K2 -> 0 | G4: 거래처 | H4: ='시트2 32품목 스티커'!#REF! -> #REF! | I4: 약 국 명 | J4: ='시트2 32품목 스티커'!#REF! -> #REF!
A5: 유효기간 | B5: ='시트2 32품목 스티커'!I2 -> 0 | C5: 전화번호 | G5: 유효기간 | H5: ='시트2 32품목 스티커'!#REF! -> #REF! | I5: 전화번호
A6: 반품수량 | B6: ='시트2 32품목 스티커'!G2 -> 0 | C6: 대표약사 | G6: 반품수량 | H6: ='시트2 32품목 스티커'!#REF! -> #REF! | I6: 대표약사
A8: 불용재고의약품 | C8: 분류번호 | D8: ='시트2 32품목 스티커'!#REF! -> #REF! | G8: 불용재고의약품 | I8: 분류번호 | J8: ='시트2 32품목 스티커'!#REF! -> #REF!
A9: 약 품 명 | B9: ='시트2 32품목 스티커'!#REF! -> #REF! | C9: 단가 | D9: ='시트2 32품목 스티커'!#REF! -> #REF! | G9: 약 품 명 | H9: ='시트2 32품목 스티커'!#REF! -> #REF! | I9: 단가 | J9: ='시트2 32품목 스티커'!#REF! -> #REF!
A10: 제약회사 | B10: ='시트2 32품목 스티커'!#REF! -> #REF! | C10: 반품금액 | D10: ='시트2 32품목 스티커'!#REF! -> #REF! | G10: 제약회사 | H10: ='시트2 32품목 스티커'!#REF! -> #REF! | I10: 반품금액 | J10: ='시트2 32품목 스티커'!#REF! -> #REF!
A11: 거래처 | B11: ='시트2 32품목 스티커'!#REF! -> #REF! | C11: 약 국 명 | D11: ='시트2 32품목 스티커'!#REF! -> #REF! | G11: 거래처 | H11: ='시트2 32품목 스티커'!#REF! -> #REF! | I11: 약 국 명 | J11: ='시트2 32품목 스티커'!#REF! -> #REF!
A12: 유효기간 | B12: ='시트2 32품목 스티커'!#REF! -> #REF! | C12: 전화번호 | G12: 유효기간 | H12: ='시트2 32품목 스티커'!#REF! -> #REF! | I12: 전화번호
A13: 반품수량 | B13: ='시트2 32품목 스티커'!#REF! -> #REF! | C13: 대표약사 | G13: 반품수량 | H13: ='시트2 32품목 스티커'!#REF! -> #REF! | I13: 대표약사
A15: 불용재고의약품 | C15: 분류번호 | D15: ='시트2 32품목 스티커'!#REF! -> #REF! | G15: 불용재고의약품 | I15: 분류번호 | J15: ='시트2 32품목 스티커'!#REF! -> #REF!
A16: 약 품 명 | B16: ='시트2 32품목 스티커'!#REF! -> #REF! | C16: 단가 | D16: ='시트2 32품목 스티커'!#REF! -> #REF! | G16: 약 품 명 | H16: ='시트2 32품목 스티커'!#REF! -> #REF! | I16: 단가 | J16: ='시트2 32품목 스티커'!#REF! -> #REF!
A17: 제약회사 | B17: ='시트2 32품목 스티커'!#REF! -> #REF! | C17: 반품금액 | D17: ='시트2 32품목 스티커'!#REF! -> #REF! | G17: 제약회사 | H17: ='시트2 32품목 스티커'!#REF! -> #REF! | I17: 반품금액 | J17: ='시트2 32품목 스티커'!#REF! -> #REF!
A18: 거래처 | B18: ='시트2 32품목 스티커'!#REF! -> #REF! | C18: 약 국 명 | D18: ='시트2 32품목 스티커'!#REF! -> #REF! | G18: 거래처 | H18: ='시트2 32품목 스티커'!#REF! -> #REF! | I18: 약 국 명 | J18: ='시트2 32품목 스티커'!#REF! -> #REF!
A19: 유효기간 | B19: ='시트2 32품목 스티커'!#REF! -> #REF! | C19: 전화번호 | G19: 유효기간 | H19: ='시트2 32품목 스티커'!#REF! -> #REF! | I19: 전화번호
A20: 반품수량 | B20: ='시트2 32품목 스티커'!#REF! -> #REF! | C20: 대표약사 | G20: 반품수량 | H20: ='시트2 32품목 스티커'!#REF! -> #REF! | I20: 대표약사
A22: 불용재고의약품 | C22: 분류번호 | D22: ='시트2 32품목 스티커'!#REF! -> #REF! | G22: 불용재고의약품 | I22: 분류번호 | J22: ='시트2 32품목 스티커'!#REF! -> #REF!
A23: 약 품 명 | B23: ='시트2 32품목 스티커'!#REF! -> #REF! | C23: 단가 | D23: ='시트2 32품목 스티커'!#REF! -> #REF! | G23: 약 품 명 | H23: ='시트2 32품목 스티커'!#REF! -> #REF! | I23: 단가 | J23: ='시트2 32품목 스티커'!#REF! -> #REF!
A24: 제약회사 | B24: ='시트2 32품목 스티커'!#REF! -> #REF! | C24: 반품금액 | D24: ='시트2 32품목 스티커'!#REF! -> #REF! | G24: 제약회사 | H24: ='시트2 32품목 스티커'!#REF! -> #REF! | I24: 반품금액 | J24: ='시트2 32품목 스티커'!#REF! -> #REF!
A25: 거래처 | B25: ='시트2 32품목 스티커'!#REF! -> #REF! | C25: 약 국 명 | D25: ='시트2 32품목 스티커'!#REF! -> #REF! | G25: 거래처 | H25: ='시트2 32품목 스티커'!#REF! -> #REF! | I25: 약 국 명 | J25: ='시트2 32품목 스티커'!#REF! -> #REF!
A26: 유효기간 | B26: ='시트2 32품목 스티커'!#REF! -> #REF! | C26: 전화번호 | G26: 유효기간 | H26: ='시트2 32품목 스티커'!#REF! -> #REF! | I26: 전화번호
A27: 반품수량 | B27: ='시트2 32품목 스티커'!#REF! -> #REF! | C27: 대표약사 | G27: 반품수량 | H27: ='시트2 32품목 스티커'!#REF! -> #REF! | I27: 대표약사
A29: 불용재고의약품 | C29: 분류번호 | D29: ='시트2 32품목 스티커'!#REF! -> #REF! | G29: 불용재고의약품 | I29: 분류번호 | J29: ='시트2 32품목 스티커'!#REF! -> #REF!
A30: 약 품 명 | B30: ='시트2 32품목 스티커'!#REF! -> #REF! | C30: 단가 | D30: ='시트2 32품목 스티커'!#REF! -> #REF! | G30: 약 품 명 | H30: ='시트2 32품목 스티커'!#REF! -> #REF! | I30: 단가 | J30: ='시트2 32품목 스티커'!#REF! -> #REF!
A31: 제약회사 | B31: ='시트2 32품목 스티커'!#REF! -> #REF! | C31: 반품금액 | D31: ='시트2 32품목 스티커'!#REF! -> #REF! | G31: 제약회사 | H31: ='시트2 32품목 스티커'!#REF! -> #REF! | I31: 반품금액 | J31: ='시트2 32품목 스티커'!#REF! -> #REF!
A32: 거래처 | B32: ='시트2 32품목 스티커'!#REF! -> #REF! | C32: 약 국 명 | D32: ='시트2 32품목 스티커'!#REF! -> #REF! | G32: 거래처 | H32: ='시트2 32품목 스티커'!#REF! -> #REF! | I32: 약 국 명 | J32: ='시트2 32품목 스티커'!#REF! -> #REF!
A33: 유효기간 | B33: ='시트2 32품목 스티커'!#REF! -> #REF! | C33: 전화번호 | G33: 유효기간 | H33: ='시트2 32품목 스티커'!#REF! -> #REF! | I33: 전화번호
A34: 반품수량 | B34: ='시트2 32품목 스티커'!#REF! -> #REF! | C34: 대표약사 | G34: 반품수량 | H34: ='시트2 32품목 스티커'!#REF! -> #REF! | I34: 대표약사
A36: 불용재고의약품 | C36: 분류번호 | D36: ='시트2 32품목 스티커'!#REF! -> #REF! | G36: 불용재고의약품 | I36: 분류번호 | J36: ='시트2 32품목 스티커'!#REF! -> #REF!
A37: 약 품 명 | B37: ='시트2 32품목 스티커'!#REF! -> #REF! | C37: 단가 | D37: ='시트2 32품목 스티커'!#REF! -> #REF! | G37: 약 품 명 | H37: ='시트2 32품목 스티커'!#REF! -> #REF! | I37: 단가 | J37: ='시트2 32품목 스티커'!#REF! -> #REF!
A38: 제약회사 | B38: ='시트2 32품목 스티커'!#REF! -> #REF! | C38: 반품금액 | D38: ='시트2 32품목 스티커'!#REF! -> #REF! | G38: 제약회사 | H38: ='시트2 32품목 스티커'!#REF! -> #REF! | I38: 반품금액 | J38: ='시트2 32품목 스티커'!#REF! -> #REF!
A39: 거래처 | B39: ='시트2 32품목 스티커'!#REF! -> #REF! | C39: 약 국 명 | D39: ='시트2 32품목 스티커'!#REF! -> #REF! | G39: 거래처 | H39: ='시트2 32품목 스티커'!#REF! -> #REF! | I39: 약 국 명 | J39: ='시트2 32품목 스티커'!#REF! -> #REF!
A40: 유효기간 | B40: ='시트2 32품목 스티커'!#REF! -> #REF! | C40: 전화번호 | G40: 유효기간 | H40: ='시트2 32품목 스티커'!#REF! -> #REF! | I40: 전화번호
A41: 반품수량 | B41: ='시트2 32품목 스티커'!#REF! -> #REF! | C41: 대표약사 | G41: 반품수량 | H41: ='시트2 32품목 스티커'!#REF! -> #REF! | I41: 대표약사
A43: 불용재고의약품 | C43: 분류번호 | D43: ='시트2 32품목 스티커'!#REF! -> #REF! | G43: 불용재고의약품 | I43: 분류번호 | J43: ='시트2 32품목 스티커'!#REF! -> #REF!
A44: 약 품 명 | B44: ='시트2 32품목 스티커'!#REF! -> #REF! | C44: 단가 | D44: ='시트2 32품목 스티커'!#REF! -> #REF! | G44: 약 품 명 | H44: ='시트2 32품목 스티커'!#REF! -> #REF! | I44: 단가 | J44: ='시트2 32품목 스티커'!#REF! -> #REF!
A45: 제약회사 | B45: ='시트2 32품목 스티커'!#REF! -> #REF! | C45: 반품금액 | D45: ='시트2 32품목 스티커'!#REF! -> #REF! | G45: 제약회사 | H45: ='시트2 32품목 스티커'!#REF! -> #REF! | I45: 반품금액 | J45: ='시트2 32품목 스티커'!#REF! -> #REF!
A46: 거래처 | B46: ='시트2 32품목 스티커'!#REF! -> #REF! | C46: 약 국 명 | D46: ='시트2 32품목 스티커'!#REF! -> #REF! | G46: 거래처 | H46: ='시트2 32품목 스티커'!#REF! -> #REF! | I46: 약 국 명 | J46: ='시트2 32품목 스티커'!#REF! -> #REF!
...
